<?xml version="1.0" ?>
<!-- =================================================================================== -->
<!-- |    This document was autogenerated by xacro from dfnder_medium.urdf.xacro       | -->
<!-- |    EDITING THIS FILE BY HAND IS NOT RECOMMENDED                                 | -->
<!-- =================================================================================== -->
<!-- 
This files describes the dfnder medium station in a classical configuration using the URDF format with XACRO

Physical description with 
    - the base
    - the mast (rotating around the AZA axis, referenced from the base)
    - the cradle axle ( rotating around the ELA axis, referenced from the mast)
    - the super elevation (can be used as a camera fixture static angle in case no ILOS is present)
    - the super traverse (can be used as a camera fixture static angle in case no ILOS is present)

hypotheses: 
	- all the inertia of the AZA axis is put at the mast level
	- all the inertia of the ELA axis is put at the cradle axle level
	- all the inertias are typical values and depend station configuration
	- Physical limitations and properties are representative but not exact and should be confirmed depending on configuration
-->
<robot>
  <!-- 
	********************************
	       MATERIALS
	********************************
        -->
  <!-- Defining a few colors as materials to distinguish the axes -->
  <material name="blue">
    <color rgba="0 0 0.8 1"/>
  </material>
  <material name="black">
    <color rgba="0 0 0 1"/>
  </material>
  <material name="white">
    <color rgba="1 1 1 1"/>
  </material>
  <material name="green">
    <color rgba="0 1 0 1"/>
  </material>
  <material name="red">
    <color rgba="1 0 0 1"/>
  </material>
  <material name="purple">
    <color rgba="1 0 1 1"/>
  </material>
  <!-- TBC -->
  <!-- TBC -->
  <!-- TBC -->
  <!-- TBC -->
  <!-- TBC -->
  <link name="base_link">
    <visual>
      <geometry>
        <cylinder length="0.1" radius="0.2"/>
      </geometry>
      <!-- Small shift of half the base length such that the station reference is at 0.0 -->
      <origin rpy="0 0 0" xyz="0 0 -0.05"/>
      <material name="red"/>
    </visual>
    <inertial>
      <mass value="1000"/>
      <!-- default mass for gazebo to be able to spawn -->
      <inertia ixx="0.0" ixy="0.0" ixz="0.0" iyy="0.0" iyz="0.0" izz="50"/>
    </inertial>
  </link>
  <!-- Mast is composed of "mast_bottom", "mast_right", "mast_left", all mast components are referenced 
	     from the base link and are thus linked at xyz = [0.0 0.0 0.0] -->
  <link name="mast_bottom">
    <visual>
      <geometry>
        <box size="0.8 0.4 0.2"/>
      </geometry>
      <origin rpy="0 0 0" xyz="0 0 0.1"/>
      <material name="white"/>
    </visual>
    <inertial>
      <mass value="10"/>
      <inertia ixx="0.0" ixy="0.0" ixz="0.0" iyy="0.0" iyz="0.0" izz="50"/>
    </inertial>
  </link>
  <joint name="aza_axis" type="continuous">
    <parent link="base_link"/>
    <child link="mast_bottom"/>
    <axis xyz="0 0 1"/>
    <origin xyz="0 0 0"/>
    <limit effort="5000" velocity="1.5707963267948966"/>
  </joint>
  <link name="mast_left">
    <visual>
      <geometry>
        <box size="0.2 0.3 0.6"/>
      </geometry>
      <origin rpy="0.2 0 0" xyz="-0.3 -0.1 0.4"/>
      <material name="white"/>
    </visual>
    <inertial>
      <mass value="0"/>
      <inertia ixx="0.0" ixy="0.0" ixz="0.0" iyy="0.0" iyz="0.0" izz="0.0"/>
    </inertial>
  </link>
  <joint name="mast_bottom_to_left" type="fixed">
    <parent link="mast_bottom"/>
    <child link="mast_left"/>
    <origin rpy="0 0 0" xyz="0 0 0"/>
  </joint>
  <link name="mast_right">
    <visual>
      <geometry>
        <box size="0.2 0.3 0.6"/>
      </geometry>
      <origin rpy="0.2 0 0" xyz="0.3 -0.1 0.4"/>
      <material name="white"/>
    </visual>
    <inertial>
      <mass value="0.01"/>
      <!-- default mass for gazebo to be able to spawn -->
      <inertia ixx="0.0" ixy="0.0" ixz="0.0" iyy="0.0" iyz="0.0" izz="0.0"/>
    </inertial>
  </link>
  <joint name="mast_bottom_to_right" type="fixed">
    <parent link="mast_bottom"/>
    <child link="mast_right"/>
    <origin rpy="0 0 0" xyz="0 0 0"/>
  </joint>
  <link name="cradle_axle">
    <visual>
      <geometry>
        <cylinder length="0.85" radius="0.075"/>
      </geometry>
      <origin rpy="1.57 0 1.57" xyz="0 0 0.0"/>
      <material name="blue"/>
    </visual>
    <inertial>
      <mass value="0.01"/>
      <!-- default mass for gazebo to be able to spawn -->
      <inertia ixx="10" ixy="0.0" ixz="0.0" iyy="0.0" iyz="0.0" izz="0.0"/>
    </inertial>
  </link>
  <link name="gun">
    <visual>
      <geometry>
        <box size="0.15 0.6 0.15"/>
      </geometry>
      <origin rpy="0 0 0" xyz="0 -0.2 0"/>
      <material name="blue"/>
    </visual>
    <inertial>
      <mass value="10"/>
      <inertia ixx="0.0" ixy="0.0" ixz="0.0" iyy="0.0" iyz="0.0" izz="0.0"/>
    </inertial>
  </link>
  <link name="gun_barrel">
    <visual>
      <geometry>
        <cylinder length="0.4" radius="0.05"/>
      </geometry>
      <origin rpy="1.57 0 0" xyz="0 0.3 0.0"/>
      <material name="blue"/>
    </visual>
    <inertial>
      <mass value="0"/>
      <inertia ixx="0.0" ixy="0.0" ixz="0.0" iyy="0.0" iyz="0.0" izz="0.0"/>
    </inertial>
  </link>
  <joint name="ela_axis" type="revolute">
    <parent link="mast_bottom"/>
    <child link="cradle_axle"/>
    <axis xyz="1 0 0 "/>
    <origin xyz="0 -0.17 0.531"/>
    <limit effort="5000" lower="-0.52" upper="1.04" velocity="1.5707963267948966"/>
  </joint>
  <joint name="cradle_axle_to_gun" type="fixed">
    <parent link="cradle_axle"/>
    <child link="gun"/>
    <origin rpy="0 0 0" xyz="0 0 0.05"/>
  </joint>
  <joint name="gun_to_barrel" type="fixed">
    <parent link="gun"/>
    <child link="gun_barrel"/>
    <origin rpy="0 0 0" xyz="0 0 0"/>
  </joint>
  <link name="sela_camera_support_left">
    <visual>
      <geometry>
        <box size="0.01 0.4 0.4"/>
      </geometry>
      <origin rpy="0 0 0" xyz="-0.005 0 0"/>
      <material name="green"/>
    </visual>
    <inertial>
      <mass value="0.01"/>
      <!-- default mass for gazebo to be able to spawn -->
      <inertia ixx="0.0" ixy="0.0" ixz="0.0" iyy="0.0" iyz="0.0" izz="0.0"/>
    </inertial>
  </link>
  <link name="sela_camera_support_bottom">
    <visual>
      <geometry>
        <box size="0.4 0.4 0.01"/>
      </geometry>
      <origin rpy="0 0 0" xyz="0 0 0"/>
      <material name="green"/>
    </visual>
    <inertial>
      <mass value="0.01"/>
      <!-- default mass for gazebo to be able to spawn -->
      <inertia ixx="0.0" ixy="0.0" ixz="0.0" iyy="0.0" iyz="0.0" izz="0.0"/>
    </inertial>
  </link>
  <joint name="sela_axis" type="revolute">
    <parent link="cradle_axle"/>
    <child link="sela_camera_support_left"/>
    <origin rpy="0 0 0" xyz="0.425 0 0"/>
    <axis xyz="1 0 0 "/>
    <limit effort="5000" lower="-2" upper="1.04" velocity="1.5707963267948966"/>
  </joint>
  <joint name="sela_camera_support_bottom_to_left" type="fixed">
    <parent link="sela_camera_support_left"/>
    <child link="sela_camera_support_bottom"/>
    <origin rpy="0 0 0" xyz="0.20 0 -0.20"/>
  </joint>
  <link name="saza_camera_box">
    <visual>
      <geometry>
        <box size="0.25 0.25 0.25"/>
      </geometry>
      <origin rpy="0 0 0" xyz="0 0 0.125"/>
      <material name="purple"/>
    </visual>
    <inertial>
      <mass value="0.01"/>
      <!-- default mass for gazebo to be able to spawn -->
      <inertia ixx="0.0" ixy="0.0" ixz="0.0" iyy="0.0" iyz="0.0" izz="0.0"/>
    </inertial>
  </link>
  <joint name="saza_axis" type="revolute">
    <parent link="sela_camera_support_left"/>
    <child link="saza_camera_box"/>
    <origin rpy="0 0 0" xyz="0.20083999999999996 0.09000000000000001 -0.098"/>
    <axis xyz="0 0 1 "/>
    <limit effort="5000" lower="-0.2" upper="0.2" velocity="1.5707963267948966"/>
  </joint>
</robot>
